Workbook

Sheet Weights
A1: Parameter | B1: Value
A2: w_base_score | B2: 1
A3: w_facilities | B3: 0.45
A4: w_confidence | B4: 1
A5: max_facilities_cap | B5: 500
A7: Notes
A8: Priority_Score = (Score*w_base_score) + (MIN(Facilities_Est,cap) * w_facilities * (Confidence/100) * w_confidence)

Sheet Research Queue
A1: Company | B1: Tier | C1: Score | D1: Facilities_Est | E1: Confidence | F1: Evidence_URL_1 | G1: Method | H1: Notes | I1: Assigned_To | J1: Status
A2: Ajinomoto Foods North America, Inc. | B2: Tier 3 | C2: 55 | D2: =IFERROR(INDEX('Company Hitlist'!$Q:$Q,MATCH($A2,'Company Hitlist'!$A:$A,0)),) | E2: =IFERROR(INDEX('Company Hitlist'!$W:$W,MATCH($A2,'Company Hitlist'!$A:$A,0)),) | F2: =IFERROR(INDEX('Company Hitlist'!$T:$T,MATCH($A2,'Company Hitlist'!$A:$A,0)),) | G2: =IFERROR(INDEX('Company Hitlist'!$V:$V,MATCH($A2,'Company Hitlist'!$A:$A,0)),) | J2: todo
A3: CHS, Inc. | B3: Tier 3 | C3: 52 | D3: =IFERROR(INDEX('Company Hitlist'!$Q:$Q,MATCH($A3,'Company Hitlist'!$A:$A,0)),) | E3: =IFERROR(INDEX('Company Hitlist'!$W:$W,MATCH($A3,'Company Hitlist'!$A:$A,0)),) | F3: =IFERROR(INDEX('Company Hitlist'!$T:$T,MATCH($A3,'Company Hitlist'!$A:$A,0)),) | G3: =IFERROR(INDEX('Company Hitlist'!$V:$V,MATCH($A3,'Company Hitlist'!$A:$A,0)),) | J3: todo
A4: APL Logistics | B4: Tier 3 | C4: 51 | D4: =IFERROR(INDEX('Company Hitlist'!$Q:$Q,MATCH($A4,'Company Hitlist'!$A:$A,0)),) | E4: =IFERROR(INDEX('Company Hitlist'!$W:$W,MATCH($A4,'Company Hitlist'!$A:$A,0)),) | F4: =IFERROR(INDEX('Company Hitlist'!$T:$T,MATCH($A4,'Company Hitlist'!$A:$A,0)),) | G4: =IFERROR(INDEX('Company Hitlist'!$V:$V,MATCH($A4,'Company Hitlist'!$A:$A,0)),) | J4: todo
A5: BarkBox | B5: Tier 3 | C5: 50 | D5: =IFERROR(INDEX('Company Hitlist'!$Q:$Q,MATCH($A5,'Company Hitlist'!$A:$A,0)),) | E5: =IFERROR(INDEX('Company Hitlist'!$W:$W,MATCH($A5,'Company Hitlist'!$A:$A,0)),) | F5: =IFERROR(INDEX('Company Hitlist'!$T:$T,MATCH($A5,'Company Hitlist'!$A:$A,0)),) | G5: =IFERROR(INDEX('Company Hitlist'!$V:$V,MATCH($A5,'Company Hitlist'!$A:$A,0)),) | J5: todo
A6: Logitech | B6: Tier 3 | C6: 50 | D6: =IFERROR(INDEX('Company Hitlist'!$Q:$Q,MATCH($A6,'Company Hitlist'!$A:$A,0)),) | E6: =IFERROR(INDEX('Company Hitlist'!$W:$W,MATCH($A6,'Company Hitlist'!$A:$A,0)),) | F6: =IFERROR(INDEX('Company Hitlist'!$T:$T,MATCH($A6,'Company Hitlist'!$A:$A,0)),) | G6: =IFERROR(INDEX('Company Hitlist'!$V:$V,MATCH($A6,'Company Hitlist'!$A:$A,0)),) | J6: todo
A7: Stitch Fix | B7: Tier 3 | C7: 50 | D7: =IFERROR(INDEX('Company Hitlist'!$Q:$Q,MATCH($A7,'Company Hitlist'!$A:$A,0)),) | E7: =IFERROR(INDEX('Company Hitlist'!$W:$W,MATCH($A7,'Company Hitlist'!$A:$A,0)),) | F7: =IFERROR(INDEX('Company Hitlist'!$T:$T,MATCH($A7,'Company Hitlist'!$A:$A,0)),) | G7: =IFERROR(INDEX('Company Hitlist'!$V:$V,MATCH($A7,'Company Hitlist'!$A:$A,0)),) | J7: todo
A8: AEO | B8: Tier 3 | C8: 48 | D8: =IFERROR(INDEX('Company Hitlist'!$Q:$Q,MATCH($A8,'Company Hitlist'!$A:$A,0)),) | E8: =IFERROR(INDEX('Company Hitlist'!$W:$W,MATCH($A8,'Company Hitlist'!$A:$A,0)),) | F8: =IFERROR(INDEX('Company Hitlist'!$T:$T,MATCH($A8,'Company Hitlist'!$A:$A,0)),) | G8: =IFERROR(INDEX('Company Hitlist'!$V:$V,MATCH($A8,'Company Hitlist'!$A:$A,0)),) | J8: todo
A9: Johnson & Johnson | B9: Tier 3 | C9: 46 | D9: =IFERROR(INDEX('Company Hitlist'!$Q:$Q,MATCH($A9,'Company Hitlist'!$A:$A,0)),) | E9: =IFERROR(INDEX('Company Hitlist'!$W:$W,MATCH($A9,'Company Hitlist'!$A:$A,0)),) | F9: =IFERROR(INDEX('Company Hitlist'!$T:$T,MATCH($A9,'Company Hitlist'!$A:$A,0)),) | G9: =IFERROR(INDEX('Company Hitlist'!$V:$V,MATCH($A9,'Company Hitlist'!$A:$A,0)),) | J9: todo
A10: Kenco | B10: Tier 3 | C10: 46 | D10: =IFERROR(INDEX('Company Hitlist'!$Q:$Q,MATCH($A10,'Company Hitlist'!$A:$A,0)),) | E10: =IFERROR(INDEX('Company Hitlist'!$W:$W,MATCH($A10,'Company Hitlist'!$A:$A,0)),) | F10: =IFERROR(INDEX('Company Hitlist'!$T:$T,MATCH($A10,'Company Hitlist'!$A:$A,0)),) | G10: =IFERROR(INDEX('Company Hitlist'!$V:$V,MATCH($A10,'Company Hitlist'!$A:$A,0)),) | J10: todo
A11: Caraway | B11: Tier 3 | C11: 45 | D11: =IFERROR(INDEX('Company Hitlist'!$Q:$Q,MATCH($A11,'Company Hitlist'!$A:$A,0)),) | E11: =IFERROR(INDEX('Company Hitlist'!$W:$W,MATCH($A11,'Company Hitlist'!$A:$A,0)),) | F11: =IFERROR(INDEX('Company Hitlist'!$T:$T,MATCH($A11,'Company Hitlist'!$A:$A,0)),) | G11: =IFERROR(INDEX('Company Hitlist'!$V:$V,MATCH($A11,'Company Hitlist'!$A:$A,0)),) | J11: todo
A12: Aterian | B12: Tier 3 | C12: 45 | D12: =IFERROR(INDEX('Company Hitlist'!$Q:$Q,MATCH($A12,'Company Hitlist'!$A:$A,0)),) | E12: =IFERROR(INDEX('Company Hitlist'!$W:$W,MATCH($A12,'Company Hitlist'!$A:$A,0)),) | F12: =IFERROR(INDEX('Company Hitlist'!$T:$T,MATCH($A12,'Company Hitlist'!$A:$A,0)),) | G12: =IFERROR(INDEX('Company Hitlist'!$V:$V,MATCH($A12,'Company Hitlist'!$A:$A,0)),) | J12: todo
A13: Globe Electric | B13: Tier 3 | C13: 45 | D13: =IFERROR(INDEX('Company Hitlist'!$Q:$Q,MATCH($A13,'Company Hitlist'!$A:$A,0)),) | E13: =IFERROR(INDEX('Company Hitlist'!$W:$W,MATCH($A13,'Company Hitlist'!$A:$A,0)),) | F13: =IFERROR(INDEX('Company Hitlist'!$T:$T,MATCH($A13,'Company Hitlist'!$A:$A,0)),) | G13: =IFERROR(INDEX('Company Hitlist'!$V:$V,MATCH($A13,'Company Hitlist'!$A:$A,0)),) | J13: todo
... A82: Global Industrial Company | B82: Tier 1 | C82: 82 | D82: =IFERROR(INDEX('Company Hitlist'!$Q:$Q,MATCH($A82,'Company Hitlist'!$A:$A,0)),) | E82: =IFERROR(INDEX('Company Hitlist'!$W:$W,MATCH($A82,'Company Hitlist'!$A:$A,0)),) | F82: =IFERROR(INDEX('Company Hitlist'!$T:$T,MATCH($A82,'Company Hitlist'!$A:$A,0)),) | G82: =IFERROR(INDEX('Company Hitlist'!$V:$V,MATCH($A82,'Company Hitlist'!$A:$A,0)),) | J82: todo

Sheet Company Hitlist
A1: Company | B1: attendees | C1: exec_ops_count | D1: ops_count | E1: proc_count | F1: sales_count | G1: tech_count | H1: max_revenue | I1: non_ops | J1: ops_share | K1: vendor_penalty | L1: mega_boost | M1: Score | N1: Tier | O1: Recommended Targets | P1: TopTitles | Q1: Facilities_Est | R1: Yards_Est | S1: Facility_Type | T1: Evidence_URL_1 | U1: Evidence_URL_2 | V1: Method | W1: Confidence | X1: Last_Verified | Y1: Enrichment_Status | Z1: Priority_Score | AA1: Priority_Rank
A2: Mars | B2: 9 | C2: 0 | D2: 6 | E2: 1 | F2: 0 | G2: 1 | I2: 1 | J2: 0.66666667 | K2: 0 | L2: 0 | M2: 35 | N2: Tier 4 | O2: Michael Ventura — Manager, Strategic Sourcing - Transportation; Mike Shaverin — Global Supply Chain Director; Meghan Charboneau — Director of Transportation; Isaiah Viera — Global Warehouse Operations Manager; Josh Mullis — Global Supply Chain Director - Mars Retail | P2: Manager, Strategic Sourcing - Transportation | Director of Transportation | SVP of Global Analytics, Digital & Data | Y2: todo | Z2: =(M2*Weights!$B$2) + (MIN(Q2,Weights!$B$5)*Weights!$B$3*(W2/100)*Weights!$B$4) | AA2: =IF(Z2= ,,RANK.EQ({pri_col_letter}{r},{pri_range},0))
A3: SEKO Logistics | B3: 7 | C3: 0 | D3: 2 | E3: 0 | F3: 0 | G3: 1 | H3: 2000000000 | I3: 1 | J3: 0.28571429 | K3: 0 | L3: 0 | M3: 35 | N3: Tier 4 | O3: Caleb Alvis — Commercial Operations Manager; Dina Stillo — Director of Program Development, Supply Chain & Logistics; Brian Bourke — Chief Commerical Officer; Brock McMorris — Vice President, Global Strategic Clients; Jamie Andrade — SVP, Product Management | P3: Chief Commerical Officer | Vice President, Global Strategic Clients | SVP, Product Management | Y3: todo | Z3: =(M3*Weights!$B$2) + (MIN(Q3,Weights!$B$5)*Weights!$B$3*(W3/100)*Weights!$B$4) | AA3: =IF(Z3= ,,RANK.EQ({pri_col_letter}{r},{pri_range},0))
A4: Wayfair | B4: 2 | C4: 0 | D4: 1 | E4: 1 | F4: 0 | G4: 0 | I4: 0 | J4: 0.5 | K4: 0 | L4: 25 | M4: 33 | N4: Tier 4 | O4: Kenneth Sine — Head of Global Procurement; Chayan Ray — Senior Manager, Global Transportation Systems | P4: Head of Global Procurement | Senior Manager, Global Transportation Systems | Y4: todo | Z4: =(M4*Weights!$B$2) + (MIN(Q4,Weights!$B$5)*Weights!$B$3*(W4/100)*Weights!$B$4) | AA4: =IF(Z4= ,,RANK.EQ({pri_col_letter}{r},{pri_range},0))
A5: Light & Wonder | B5: 12 | C5: 0 | D5: 2 | E5: 6 | F5: 0 | G5: 0 | I5: 0 | J5: 0.16666667 | K5: 0 | L5: 0 | M5: 32 | N5: Tier 4 | O5: Jennifer Krueger — Vice President, Planning & Purchasing; Eric Eileraas — Sr Director Logistics; Rachael Leggett — Sr Director, Supply Chain Strategy & Demand Planning; Deb Withers — Sr Manager, Purchasing; Eric Sill — Director, Supply Planning & Purchasing | P5: Vice President, Planning & Purchasing | COO | Vice President, Field Services | Y5: todo | Z5: =(M5*Weights!$B$2) + (MIN(Q5,Weights!$B$5)*Weights!$B$3*(W5/100)*Weights!$B$4) | AA5: =IF(Z5= ,,RANK.EQ({pri_col_letter}{r},{pri_range},0))
A6: KBX | B6: 7 | C6: 1 | D6: 2 | E6: 1 | F6: 0 | G6: 0 | I6: 0 | J6: 0.28571429 | K6: 0 | L6: 0 | M6: 32 | N6: Tier 4 | O6: Jamie Hess — VP, Global Transportation Procurement; David Bennett — Sr. Managing Director, International Logistics; Richard Swan — KBX President; Ryan Winter — CFO; Scott Reed — CIO | P6: VP, Global Transportation Procurement | Sr. Managing Director, International Logistics | KBX President | Y6: todo | Z6: =(M6*Weights!$B$2) + (MIN(Q6,Weights!$B$5)*Weights!$B$3*(W6/100)*Weights!$B$4) | AA6: =IF(Z6= ,,RANK.EQ({pri_col_letter}{r},{pri_range},0))
A7: iFIT | B7: 5 | C7: 1 | D7: 3 | E7: 0 | F7: 0 | G7: 0 | I7: 0 | J7: 0.6 | K7: 0 | L7: 0 | M7: 32 | N7: Tier 4 | O7: Robert Critchley — VP, Transportation & Warehousing; Mike Buttars — Reverse Logistics; Ron Stimson — Director of Reverse logistics; Paul Bozich — Director of Home Delivery; Chelsey Porter — Carrier Relations Manager | P7: VP, Transportation & Warehousing | Reverse Logistics | Director of Reverse logistics | Y7: todo | Z7: =(M7*Weights!$B$2) + (MIN(Q7,Weights!$B$5)*Weights!$B$3*(W7/100)*Weights!$B$4) | AA7: =IF(Z7= ,,RANK.EQ({pri_col_letter}{r},{pri_range},0))
A8: Nike | B8: 3 | C8: 0 | D8: 1 | E8: 0 | F8: 0 | G8: 0 | I8: 0 | J8: 0.33333333 | K8: 0 | L8: 25 | M8: 32 | N8: Tier 4 | O8: Vishal Arya — Sr Director of Transportation and Trade; Lukesh Singla — Material Planning Leader; Brian Gooch — Sr. Manager, Capacity Performance and Planning | P8: Sr Director of Transportation and Trade | Material Planning Leader | Sr. Manager, Capacity Performance and Planning | Y8: todo | Z8: =(M8*Weights!$B$2) + (MIN(Q8,Weights!$B$5)*Weights!$B$3*(W8/100)*Weights!$B$4) | AA8: =IF(Z8= ,,RANK.EQ({pri_col_letter}{r},{pri_range},0))
A9: Aristocrat Gaming | B9: 4 | C9: 1 | D9: 3 | E9: 0 | F9: 0 | G9: 1 | I9: 1 | J9: 0.75 | K9: 0 | L9: 0 | M9: 31 | N9: Tier 4 | O9: Mihir Wagh — SVP, GSC Manufacturing & Logistics; Caleb Lawrence — Senior Analyst Global Logistics; Erin Turner — Sr. Manager, Global Logistics; Amit Bakuli — VP-Manufacturing Engineering | P9: SVP, GSC Manufacturing & Logistics | VP-Manufacturing Engineering | Senior Analyst Global Logistics | Y9: todo | Z9: =(M9*Weights!$B$2) + (MIN(Q9,Weights!$B$5)*Weights!$B$3*(W9/100)*Weights!$B$4) | AA9: =IF(Z9= ,,RANK.EQ({pri_col_letter}{r},{pri_range},0))
A10: Peloton Interactive | B10: 4 | C10: 1 | D10: 2 | E10: 2 | F10: 0 | G10: 0 | I10: 0 | J10: 0.5 | K10: 0 | L10: 0 | M10: 31 | N10: Tier 4 | O10: Andy Rendich — Chief Supply Chain Officer; David Beyar — Sr. Manager, Transportation; Angad Gadhok — Senior Manager, Procurement; Bharat Nair — Category Manager, Procurement | P10: Chief Supply Chain Officer | Sr. Manager, Transportation | Senior Manager, Procurement | Y10: todo | Z10: =(M10*Weights!$B$2) + (MIN(Q10,Weights!$B$5)*Weights!$B$3*(W10/100)*Weights!$B$4) | AA10: =IF(Z10= ,,RANK.EQ({pri_col_letter}{r},{pri_range},0))
A11: Philips | B11: 4 | C11: 1 | D11: 3 | E11: 0 | F11: 0 | G11: 0 | I11: 0 | J11: 0.75 | K11: 0 | L11: 0 | M11: 31 | N11: Tier 4 | O11: Birger Buesching — Head of Supply Chain North America, Personal Health; Ryan Ganger — Transportation Leader North America; Marc Koumoundouros — Supply Chain Leader Canada; Laura de Chiara — Director Transformation and Integration | P11: Head of Supply Chain North America, Personal Health | Transportation Leader North America | Supply Chain Leader Canada | Y11: todo | Z11: =(M11*Weights!$B$2) + (MIN(Q11,Weights!$B$5)*Weights!$B$3*(W11/100)*Weights!$B$4) | AA11: =IF(Z11= ,,RANK.EQ({pri_col_letter}{r},{pri_range},0))
A12: Tyson Foods | B12: 2 | C12: 0 | D12: 1 | E12: 0 | F12: 0 | G12: 0 | I12: 0 | J12: 0.5 | K12: 0 | L12: 25 | M12: 31 | N12: Tier 4 | O12: Chris Plant — Director of Transportation; Kevin Corrigan — Associate Director, Business Process & Systems | P12: Director of Transportation | Associate Director, Business Process & Systems | Y12: todo | Z12: =(M12*Weights!$B$2) + (MIN(Q12,Weights!$B$5)*Weights!$B$3*(W12/100)*Weights!$B$4) | AA12: =IF(Z12= ,,RANK.EQ({pri_col_letter}{r},{pri_range},0))
A13: AT&T | B13: 6 | C13: 0 | D13: 6 | E13: 0 | F13: 0 | G13: 0 | I13: 0 | J13: 1 | K13: 0 | L13: 0 | M13: 30 | N13: Tier 4 | O13: Ellen Valencia — AVP Planning and Logistics; Jawad Masood — Director Planning and Logistics; Kent McCormick — Director Supply Planning/Logistics; Kyle Meyer — Director Planning and Logistics; Meg Birchfiled — Director Planning & Logistics | P13: AVP Planning and Logistics | Director Planning and Logistics | Director Supply Planning/Logistics | Y13: todo | Z13: =(M13*Weights!$B$2) + (MIN(Q13,Weights!$B$5)*Weights!$B$3*(W13/100)*Weights!$B$4) | AA13: =IF(Z13= ,,RANK.EQ({pri_col_letter}{r},{pri_range},0))
A14: Google Cloud | B14: 5 | C14: 1 | D14: 4 | E14: 0 | F14: 3 | G14: 2 | I14: 5 | J14: 0.8 | K14: 0 | L14: 0 | M14: 30 | N14: Tier 4 | O14: Mike Mandeville — Head of Customer Engineering, Logistics; Shayna Zweiback — Regional Marketing Lead, South and Logistics; Peter Blum — Director, US Logistics Sales; Ashwin Sridhar — Global Solutions Lead, Industry AI; Yewande Badewole — Global GTM Practice Architect - Logistics & Supply Chain | P14: Head of Customer Engineering, Logistics | Global Solutions Lead, Industry AI | Regional Marketing Lead, South and Logistics | Y14: todo | Z14: =(M14*Weights!$B$2) + (MIN(Q14,Weights!$B$5)*Weights!$B$3*(W14/100)*Weights!$B$4) | AA14: =IF(Z14= ,,RANK.EQ({pri_col_letter}{r},{pri_range},0))
A15: Dermalogica | B15: 3 | C15: 1 | D15: 3 | E15: 0 | F15: 0 | G15: 1 | I15: 1 | J15: 1 | K15: 0 | L15: 0 | M15: 30 | N15: Tier 4 | O15: John McGuinn — VP Operations; Jason Brown — Director Logistics & Warehousing; Ashley Deleonardis — Supply Chain Process Architect | P15: VP Operations | Director Logistics & Warehousing | Supply Chain Process Architect | Y15: todo | Z15: =(M15*Weights!$B$2) + (MIN(Q15,Weights!$B$5)*Weights!$B$3*(W15/100)*Weights!$B$4) | AA15: =IF(Z15= ,,RANK.EQ({pri_col_letter}{r},{pri_range},0))
... A22: Kuehne + Nagel | B22: 4 | C22: 0 | D22: 0 | E22: 0 | F22: 0 | G22: 0 | I22: 0 | J22: 0 | K22: 0 | L22: 25 | M22: 29 | N22: Tier 4 | O22: David Cornett — VP Healthcare Americas; Donald Potter — VP Consumer Americas; Liam Harris — VP Technology Americas; Ryan Pope — Director, Key Accounts Development | P22: VP Healthcare Americas | VP Consumer Americas | VP Technology Americas | Y22: todo | Z22: =(M22*Weights!$B$2) + (MIN(Q22,Weights!$B$5)*Weights!$B$3*(W22/100)*Weights!$B$4) | AA22: =IF(Z22= ,,RANK.EQ({pri_col_letter}{r},{pri_range},0))
A23: Zero Down Supply Chain Solutions | B23: 5 | C23: 1 | D23: 1 | E23: 0 | F23: 1 | G23: 0 | H23: 54436000 | I23: 1 | J23: 0.2 | K23: 0 | L23: 0 | M23: 28 | N23: Tier 4 | O23: Saxon McBride — Vice President of Operations; Brad McBride — CEO & Founder; Reinaldo Marin — COO; James Reilly II — Director of Client Acquisition; Rebecca McBride — Director of Business Development | P23: Vice President of Operations | CEO & Founder | COO | Y23: todo | Z23: =(M23*Weights!$B$2) + (MIN(Q23,Weights!$B$5)*Weights!$B$3*(W23/100)*Weights!$B$4) | AA23: =IF(Z23= ,,RANK.EQ({pri_col_letter}{r},{pri_range},0))
A24: Hunter Douglas | B24: 3 | C24: 1 | D24: 2 | E24: 1 | F24: 0 | G24: 0 | I24: 0 | J24: 0.66666667 | K24: 0 | L24: 0 | M24: 28 | N24: Tier 4 | O24: Nikki Soss — Head of Enterprise Logistics & Distribution; Andrew Curtin — Customer Delivery Logistics Leader; Christian Schaffner — Global Category Director - Freight & Packaging Procurement | P24: Head of Enterprise Logistics & Distribution | Customer Delivery Logistics Leader | Global Category Director - Freight & Packaging Procurement | Y24: todo | Z24: =(M24*Weights!$B$2) + (MIN(Q24,Weights!$B$5)*Weights!$B$3*(W24/100)*Weights!$B$4) | AA24: =IF(Z24= ,,RANK.EQ({pri_col_letter}{r},{pri_range},0))
A25: Revolve | B25: 3 | C25: 1 | D25: 2 | E25: 1 | F25: 0 | G25: 0 | I25: 0 | J25: 0.66666667 | K25: 0 | L25: 0 | M25: 28 | N25: Tier 4 | O25: Heather Burke — SVP Logistics & Customer Experience; Tony (King) Chow — Sr Director of Operations; Blanka Holubcova — Sr Purchasing Manager | P25: SVP Logistics & Customer Experience | Sr Director of Operations | Sr Purchasing Manager | Y25: todo | Z25: =(M25*Weights!$B$2) + (MIN(Q25,Weights!$B$5)*Weights!$B$3*(W25/100)*Weights!$B$4) | AA25: =IF(Z25= ,,RANK.EQ({pri_col_letter}{r},{pri_range},0))
A26: SAMSUNG SDS | B26: 10 | C26: 1 | D26: 1 | E26: 0 | F26: 1 | G26: 0 | I26: 1 | J26: 0.1 | K26: 0 | L26: 0 | M26: 27 | N26: Tier 4 | O26: Wilco Koers — Vice President Contract Logistics; Seungpyo Hong — Head of Business Team; Sungju Kim — Vice President; Jihyun Lim — Vice President; Sunggon Kim — Vice President | P26: Vice President Contract Logistics | Head of Business Team | Vice President | Y26: todo | Z26: =(M26*Weights!$B$2) + (MIN(Q26,Weights!$B$5)*Weights!$B$3*(W26/100)*Weights!$B$4) | AA26: =IF(Z26= ,,RANK.EQ({pri_col_letter}{r},{pri_range},0))
A27: Backhaul Direct | B27: 4 | C27: 1 | D27: 2 | E27: 0 | F27: 0 | G27: 0 | I27: 0 | J27: 0.5 | K27: 0 | L27: 0 | M27: 27 | N27: Tier 4 | O27: Dylan Murphy — President & Chief Operations Officer; Dylan Mollo — Tech Operations Lead; Gregory Harris — Founder/CEO; Scott Mulholland — Senior Vice President | P27: President & Chief Operations Officer | Tech Operations Lead | Founder/CEO | Y27: todo | Z27: =(M27*Weights!$B$2) + (MIN(Q27,Weights!$B$5)*Weights!$B$3*(W27/100)*Weights!$B$4) | AA27: =IF(Z27= ,,RANK.EQ({pri_col_letter}{r},{pri_range},0))
A28: Fives Intralogistics Corp. | B28: 4 | C28: 1 | D28: 3 | E28: 0 | F28: 2 | G28: 0 | I28: 2 | J28: 0.75 | K28: 0 | L28: 0 | M28: 27 | N28: Tier 4 | O28: Phillip Agans — VP of Warehouse & Distribution Solutions; Mike Stearns — Director of Warehouse and Distribution; Brad Perry — Director of Warehouse & Distribution Sales; Allison Myers — Director of Marketing & Communications | P28: VP of Warehouse & Distribution Solutions | Director of Warehouse and Distribution | Director of Warehouse & Distribution Sales | Y28: todo | Z28: =(M28*Weights!$B$2) + (MIN(Q28,Weights!$B$5)*Weights!$B$3*(W28/100)*Weights!$B$4) | AA28: =IF(Z28= ,,RANK.EQ({pri_col_letter}{r},{pri_range},0))
A29: Owens Corning | B29: 2 | C29: 1 | D29: 2 | E29: 1 | F29: 0 | G29: 0 | I29: 0 | J29: 1 | K29: 0 | L29: 0 | M29: 27 | N29: Tier 4 | O29: Mohamed Saleh — Head of Logistics & Real Estate Sourcing & Supply Chain; Andrea Webster — Distribution and Warehouse Leader | P29: Head of Logistics & Real Estate Sourcing & Supply Chain | Distribution and Warehouse Leader | Y29: todo | Z29: =(M29*Weights!$B$2) + (MIN(Q29,Weights!$B$5)*Weights!$B$3*(W29/100)*Weights!$B$4) | AA29: =IF(Z29= ,,RANK.EQ({pri_col_letter}{r},{pri_range},0))
A30: Port of Miami | B30: 2 | C30: 0 | D30: 0 | E30: 0 | F30: 0 | G30: 0 | I30: 0 | J30: 0 | K30: 0 | L30: 25 | M30: 27 | N30: Tier 4 | O30: Chris Hudtwalcker — Head of Innovation; Gustavo Grande — Head of Innovation | P30: Head of Innovation | Y30: todo | Z30: =(M30*Weights!$B$2) + (MIN(Q30,Weights!$B$5)*Weights!$B$3*(W30/100)*Weights!$B$4) | AA30: =IF(Z30= ,,RANK.EQ({pri_col_letter}{r},{pri_range},0))
A31: FabFitFun | B31: 3 | C31: 1 | D31: 2 | E31: 0 | F31: 0 | G31: 1 | I31: 1 | J31: 0.66666667 | K31: 0 | L31: 0 | M31: 26 | N31: Tier 4 | O31: Julian VanErlach — SVP, Global Supply Chain & Customer Service; Nathan Goodrich — Sr. Director of Inventory and Logistics; Mark Gavin — Sr Director, Global IT | P31: SVP, Global Supply Chain & Customer Service | Sr. Director of Inventory and Logistics | Sr Director, Global IT | Y31: todo | Z31: =(M31*Weights!$B$2) + (MIN(Q31,Weights!$B$5)*Weights!$B$3*(W31/100)*Weights!$B$4) | AA31: =IF(Z31= ,,RANK.EQ({pri_col_letter}{r},{pri_range},0))
A32: NRS | B32: 3 | C32: 1 | D32: 2 | E32: 0 | F32: 0 | G32: 0 | I32: 0 | J32: 0.66666667 | K32: 0 | L32: 0 | M32: 26 | N32: Tier 4 | O32: Anthony Mayor — SVP Distribution; Christian Klein — Director of Operations Strategy; Jon Hoch — COO | P32: SVP Distribution | Director of Operations Strategy | COO | Y32: todo | Z32: =(M32*Weights!$B$2) + (MIN(Q32,Weights!$B$5)*Weights!$B$3*(W32/100)*Weights!$B$4) | AA32: =IF(Z32= ,,RANK.EQ({pri_col_letter}{r},{pri_range},0))
A33: Sobel-Westex | B33: 3 | C33: 1 | D33: 2 | E33: 0 | F33: 0 | G33: 0 | I33: 0 | J33: 0.66666667 | K33: 0 | L33: 0 | M33: 26 | N33: Tier 4 | O33: Alex Alarcon — Chief Administration & Operations Officer; Mike Ramirez — Project Logistics & Supply Chain Management; Luis Toro — Chief Information Officer | P33: Chief Administration & Operations Officer | Chief Information Officer | Project Logistics & Supply Chain Management | Y33: todo | Z33: =(M33*Weights!$B$2) + (MIN(Q33,Weights!$B$5)*Weights!$B$3*(W33/100)*Weights!$B$4) | AA33: =IF(Z33= ,,RANK.EQ({pri_col_letter}{r},{pri_range},0))
A34: APM Terminals - Los Angeles | B34: 1 | C34: 0 | D34: 0 | E34: 0 | F34: 0 | G34: 0 | I34: 0 | J34: 0 | K34: 0 | L34: 25 | M34: 26 | N34: Tier 4 | O34: Ashley Esparza — Key Client Director | P34: Key Client Director | Y34: todo | Z34: =(M34*Weights!$B$2) + (MIN(Q34,Weights!$B$5)*Weights!$B$3*(W34/100)*Weights!$B$4) | AA34: =IF(Z34= ,,RANK.EQ({pri_col_letter}{r},{pri_range},0))
A35: Amazon Robotics | B35: 1 | C35: 0 | D35: 0 | E35: 0 | F35: 0 | G35: 1 | I35: 1 | J35: 0 | K35: 0 | L35: 25 | M35: 26 | N35: Tier 4 | O35: Tej Sheth — Lead Solutions Design Engineer | P35: Lead Solutions Design Engineer | Y35: todo | Z35: =(M35*Weights!$B$2) + (MIN(Q35,Weights!$B$5)*Weights!$B$3*(W35/100)*Weights!$B$4) | AA35: =IF(Z35= ,,RANK.EQ({pri_col_letter}{r},{pri_range},0))
... A69: The Home Depot | B69: 11 | C69: 0 | D69: 1 | E69: 0 | F69: 2 | G69: 3 | I69: 5 | J69: 0.090909091 | K69: 12 | L69: 25 | M69: 24 | N69: Tier 4 | O69: Stuart Kilgus — DC Engineer, Innovation & Automation; Chris Smith — Vice President, Information Technology; Dan Jarvis — Vice President, Engineering & Automation; Jeff Andreski — Sr. Director, Information Technology; Joanna Kronberg — Director, Innovation & Automation | P69: Vice President, Information Technology | Vice President, Engineering & Automation | DC Engineer, Innovation & Automation | Y69: todo | Z69: =(M69*Weights!$B$2) + (MIN(Q69,Weights!$B$5)*Weights!$B$3*(W69/100)*Weights!$B$4) | AA69: =IF(Z69= ,,RANK.EQ({pri_col_letter}{r},{pri_range},0))
A70: FlavorCloud | B70: 7 | C70: 1 | D70: 1 | E70: 0 | F70: 1 | G70: 1 | H70: 12000000 | I70: 2 | J70: 0.14285714 | K70: 0 | L70: 0 | M70: 24 | N70: Tier 4 | O70: Sebastian Wouters — VP Network Operations; Maia Benson — Chief Business Officer; Rathna Sharad — CEO & Co-Founder; Rathna Sharad — CEO; Sharad Kylasam — VP Product | P70: VP Network Operations | Chief Business Officer | CEO & Co-Founder | Y70: todo | Z70: =(M70*Weights!$B$2) + (MIN(Q70,Weights!$B$5)*Weights!$B$3*(W70/100)*Weights!$B$4) | AA70: =IF(Z70= ,,RANK.EQ({pri_col_letter}{r},{pri_range},0))
A71: Costco | B71: 6 | C71: 0 | D71: 1 | E71: 0 | F71: 0 | G71: 3 | I71: 3 | J71: 0.16666667 | K71: 12 | L71: 25 | M71: 23 | N71: Tier 4 | O71: Scott Wibert — Supply Chain SA/Security; Brian McBride — Global IT/Innovation; Kate Domer — Innovation Analyst; Krissie Connors — Analyst - Innovation; Troy Ness — Director of Global Innovation | P71: Supply Chain SA/Security | Global IT/Innovation | Innovation Analyst | Y71: todo | Z71: =(M71*Weights!$B$2) + (MIN(Q71,Weights!$B$5)*Weights!$B$3*(W71/100)*Weights!$B$4) | AA71: =IF(Z71= ,,RANK.EQ({pri_col_letter}{r},{pri_range},0))
A72: Infor | B72: 6 | C72: 1 | D72: 1 | E72: 0 | F72: 1 | G72: 0 | I72: 1 | J72: 0.16666667 | K72: 0 | L72: 0 | M72: 23 | N72: Tier 4 | O72: Mike Herber — VP, Supply Chain Solutions; Doug Zahour — VP, Infor Nexus; Jason Simcox — VP, Infor Nexus; Jessica Reed — Sr. Account Manager; Luke Anderson — Sr. Account Manager | P72: VP, Supply Chain Solutions | VP, Infor Nexus | Sr. Account Manager | Y72: todo | Z72: =(M72*Weights!$B$2) + (MIN(Q72,Weights!$B$5)*Weights!$B$3*(W72/100)*Weights!$B$4) | AA72: =IF(Z72= ,,RANK.EQ({pri_col_letter}{r},{pri_range},0))
A73: Metro Supply Chain | B73: 6 | C73: 1 | D73: 1 | E73: 0 | F73: 1 | G73: 0 | I73: 1 | J73: 0.16666667 | K73: 0 | L73: 0 | M73: 23 | N73: Tier 4 | O73: Chris Galindo — President- Supply Chain Services; Sean Cowie — VP Customer Solutions; Pierre Lutfy — Chief Development Officer; Glenn Hunter — Senior Director Implementation Services; Monica Burger — Director Applications Implementation and Support | P73: President- Supply Chain Services | VP Customer Solutions | Chief Development Officer | Y73: todo | Z73: =(M73*Weights!$B$2) + (MIN(Q73,Weights!$B$5)*Weights!$B$3*(W73/100)*Weights!$B$4) | AA73: =IF(Z73= ,,RANK.EQ({pri_col_letter}{r},{pri_range},0))
A74: Neovia Logistics | B74: 6 | C74: 1 | D74: 1 | E74: 1 | F74: 2 | G74: 0 | I74: 2 | J74: 0.16666667 | K74: 0 | L74: 0 | M74: 23 | N74: Tier 4 | O74: Jacques Retief — Chief Operations Officer; Elaine Evans — Senior Global Procurement Manager; Mike Fahy — Chief Executive Officer; Bethany Peek — Communications Specialist; Dan Bombrys — Vice President Customer Success | P74: Chief Operations Officer | Chief Executive Officer | Senior Global Procurement Manager | Y74: todo | Z74: =(M74*Weights!$B$2) + (MIN(Q74,Weights!$B$5)*Weights!$B$3*(W74/100)*Weights!$B$4) | AA74: =IF(Z74= ,,RANK.EQ({pri_col_letter}{r},{pri_range},0))
A75: Manifest.eco | B75: 4 | C75: 1 | D75: 1 | E75: 0 | F75: 0 | G75: 0 | I75: 0 | J75: 0.25 | K75: 0 | L75: 0 | M75: 23 | N75: Tier 4 | O75: Max Stevens — SVP Fulfillment; Cole Wenzel — SVP Customer; George Wojciechowski — CEO; Robert Sixsmith — COO | P75: SVP Fulfillment | SVP Customer | CEO | Y75: todo | Z75: =(M75*Weights!$B$2) + (MIN(Q75,Weights!$B$5)*Weights!$B$3*(W75/100)*Weights!$B$4) | AA75: =IF(Z75= ,,RANK.EQ({pri_col_letter}{r},{pri_range},0))
A76: Crane Worldwide Logistics | B76: 3 | C76: 0 | D76: 0 | E76: 0 | F76: 0 | G76: 0 | H76: 1000000000 | I76: 0 | J76: 0 | K76: 0 | L76: 0 | M76: 23 | N76: Tier 4 | O76: Brannon Kuykendall — Chief Information Officer; Dylan Ross — CFO; Jared Crane — CEO | P76: CFO | CEO | Chief Information Officer | Y76: todo | Z76: =(M76*Weights!$B$2) + (MIN(Q76,Weights!$B$5)*Weights!$B$3*(W76/100)*Weights!$B$4) | AA76: =IF(Z76= ,,RANK.EQ({pri_col_letter}{r},{pri_range},0))
A77: Acuity Brands | B77: 2 | C77: 1 | D77: 1 | E77: 1 | F77: 0 | G77: 0 | I77: 0 | J77: 0.5 | K77: 0 | L77: 0 | M77: 23 | N77: Tier 4 | O77: Joe DeFrancesco — Head of Operations; Jeff Grossman — Head of Sourcing | P77: Head of Operations | Head of Sourcing | Y77: todo | Z77: =(M77*Weights!$B$2) + (MIN(Q77,Weights!$B$5)*Weights!$B$3*(W77/100)*Weights!$B$4) | AA77: =IF(Z77= ,,RANK.EQ({pri_col_letter}{r},{pri_range},0))
A78: Glīd | B78: 2 | C78: 1 | D78: 2 | E78: 0 | F78: 1 | G78: 0 | I78: 1 | J78: 1 | K78: 0 | L78: 0 | M78: 23 | N78: Tier 4 | O78: Ankit Malhotra — Head of Operations; Aaron Stieglitz — Sales & Operations Lead | P78: Head of Operations | Sales & Operations Lead | Y78: todo | Z78: =(M78*Weights!$B$2) + (MIN(Q78,Weights!$B$5)*Weights!$B$3*(W78/100)*Weights!$B$4) | AA78: =IF(Z78= ,,RANK.EQ({pri_col_letter}{r},{pri_range},0))
A79: Martinrea International | B79: 2 | C79: 1 | D79: 1 | E79: 1 | F79: 0 | G79: 0 | I79: 0 | J79: 0.5 | K79: 0 | L79: 0 | M79: 23 | N79: Tier 4 | O79: Megan Hunter — Executive Vice President Procurement and Supply Chain Operations; Rachel Handbury — Director of Sustainability | P79: Executive Vice President Procurement and Supply Chain Operations | Director of Sustainability | Y79: todo | Z79: =(M79*Weights!$B$2) + (MIN(Q79,Weights!$B$5)*Weights!$B$3*(W79/100)*Weights!$B$4) | AA79: =IF(Z79= ,,RANK.EQ({pri_col_letter}{r},{pri_range},0))
...

Sheet People Hitlist
A1: Name | B1: Category | C1: Job Title | D1: Company | E1: Country | F1: Qualified | G1: Revenue | H1: PersonScore | I1: is_ops | J1: is_exec | K1: is_exec_ops | L1: is_proc | M1: is_sales | N1: Company_Priority_Rank | O1: Company_Priority_Tier | P1: Owner | Q1: Outreach_Status | R1: Message_V1 | S1: Connect_Report_Link
A2: Sheetal Shah | B2: Speaker | C2: VP of Supply Chain and Chief Procurement Officer | D2: PPL Electric | H2: 37 | I2: TRUE | J2: TRUE | K2: TRUE | L2: TRUE | M2: FALSE | N2: =IFERROR(INDEX('Company Hitlist'!$AA:$AA,MATCH(D2,'Company Hitlist'!$A:$A,0)),) | O2: =IFERROR(INDEX('Company Hitlist'!$N:$N,MATCH(D2,'Company Hitlist'!$A:$A,0)),) | Q2: todo
A3: Jeff Adams | B3: Attendee | C3: VP of Strategic Sourcing & Inbound Logistics | D3: Apothecary Products | H3: 34 | I3: TRUE | J3: TRUE | K3: TRUE | L3: TRUE | M3: FALSE | N3: =IFERROR(INDEX('Company Hitlist'!$AA:$AA,MATCH(D3,'Company Hitlist'!$A:$A,0)),) | O3: =IFERROR(INDEX('Company Hitlist'!$N:$N,MATCH(D3,'Company Hitlist'!$A:$A,0)),) | Q3: todo
A4: Clark Howard | B4: Attendee | C4: Chief Supply Chain and Procurement Officer | D4: Butcher Box | H4: 34 | I4: TRUE | J4: TRUE | K4: TRUE | L4: TRUE | M4: FALSE | N4: =IFERROR(INDEX('Company Hitlist'!$AA:$AA,MATCH(D4,'Company Hitlist'!$A:$A,0)),) | O4: =IFERROR(INDEX('Company Hitlist'!$N:$N,MATCH(D4,'Company Hitlist'!$A:$A,0)),) | Q4: todo
A5: Terry Frizelle | B5: Attendee | C5: Head of Logistics Procurement | D5: Dell Technologies | F5: Yes | H5: 34 | I5: TRUE | J5: TRUE | K5: TRUE | L5: TRUE | M5: FALSE | N5: =IFERROR(INDEX('Company Hitlist'!$AA:$AA,MATCH(D5,'Company Hitlist'!$A:$A,0)),) | O5: =IFERROR(INDEX('Company Hitlist'!$N:$N,MATCH(D5,'Company Hitlist'!$A:$A,0)),) | Q5: todo
A6: Randy Pappal | B6: Attendee | C6: VP Purchasing and Supply Chain | D6: Gentex Corporation | H6: 34 | I6: TRUE | J6: TRUE | K6: TRUE | L6: TRUE | M6: FALSE | N6: =IFERROR(INDEX('Company Hitlist'!$AA:$AA,MATCH(D6,'Company Hitlist'!$A:$A,0)),) | O6: =IFERROR(INDEX('Company Hitlist'!$N:$N,MATCH(D6,'Company Hitlist'!$A:$A,0)),) | Q6: todo
A7: Jamie Hess | B7: Attendee | C7: VP, Global Transportation Procurement | D7: KBX | H7: 34 | I7: TRUE | J7: TRUE | K7: TRUE | L7: TRUE | M7: FALSE | N7: =IFERROR(INDEX('Company Hitlist'!$AA:$AA,MATCH(D7,'Company Hitlist'!$A:$A,0)),) | O7: =IFERROR(INDEX('Company Hitlist'!$N:$N,MATCH(D7,'Company Hitlist'!$A:$A,0)),) | Q7: todo
A8: Samia Kaci | B8: Attendee | C8: Vice President of Sourcing and Supply Chain AVD | D8: Legrand | H8: 34 | I8: TRUE | J8: TRUE | K8: TRUE | L8: TRUE | M8: FALSE | N8: =IFERROR(INDEX('Company Hitlist'!$AA:$AA,MATCH(D8,'Company Hitlist'!$A:$A,0)),) | O8: =IFERROR(INDEX('Company Hitlist'!$N:$N,MATCH(D8,'Company Hitlist'!$A:$A,0)),) | Q8: todo
A9: Megan Hunter | B9: Attendee | C9: Executive Vice President Procurement and Supply Chain Operations | D9: Martinrea International | H9: 34 | I9: TRUE | J9: TRUE | K9: TRUE | L9: TRUE | M9: FALSE | N9: =IFERROR(INDEX('Company Hitlist'!$AA:$AA,MATCH(D9,'Company Hitlist'!$A:$A,0)),) | O9: =IFERROR(INDEX('Company Hitlist'!$N:$N,MATCH(D9,'Company Hitlist'!$A:$A,0)),) | Q9: todo
A10: Chris Huggins | B10: Attendee | C10: Head of Logistics and Procurement | D10: Operation BBQ Relief | E10: United States | H10: 34 | I10: TRUE | J10: TRUE | K10: TRUE | L10: TRUE | M10: FALSE | N10: =IFERROR(INDEX('Company Hitlist'!$AA:$AA,MATCH(D10,'Company Hitlist'!$A:$A,0)),) | O10: =IFERROR(INDEX('Company Hitlist'!$N:$N,MATCH(D10,'Company Hitlist'!$A:$A,0)),) | Q10: todo
A11: Mohamed Saleh | B11: Attendee | C11: Head of Logistics & Real Estate Sourcing & Supply Chain | D11: Owens Corning | H11: 34 | I11: TRUE | J11: TRUE | K11: TRUE | L11: TRUE | M11: FALSE | N11: =IFERROR(INDEX('Company Hitlist'!$AA:$AA,MATCH(D11,'Company Hitlist'!$A:$A,0)),) | O11: =IFERROR(INDEX('Company Hitlist'!$N:$N,MATCH(D11,'Company Hitlist'!$A:$A,0)),) | Q11: todo
A12: Miguel Miciano | B12: Attendee | C12: SVP Procurement & Logistics | D12: Pomona Farming | H12: 34 | I12: TRUE | J12: TRUE | K12: TRUE | L12: TRUE | M12: FALSE | N12: =IFERROR(INDEX('Company Hitlist'!$AA:$AA,MATCH(D12,'Company Hitlist'!$A:$A,0)),) | O12: =IFERROR(INDEX('Company Hitlist'!$N:$N,MATCH(D12,'Company Hitlist'!$A:$A,0)),) | Q12: todo
A13: Lance Starks | B13: Attendee | C13: Vice President - Global Supply Chain & Sourcing | D13: Shaw Industries | H13: 34 | I13: TRUE | J13: TRUE | K13: TRUE | L13: TRUE | M13: FALSE | N13: =IFERROR(INDEX('Company Hitlist'!$AA:$AA,MATCH(D13,'Company Hitlist'!$A:$A,0)),) | O13: =IFERROR(INDEX('Company Hitlist'!$N:$N,MATCH(D13,'Company Hitlist'!$A:$A,0)),) | Q13: todo
A14: Andrew Sylling | B14: Attendee | C14: Head of Procurement, Logistics North America | D14: Unilever | H14: 34 | I14: TRUE | J14: TRUE | K14: TRUE | L14: TRUE | M14: FALSE | N14: =IFERROR(INDEX('Company Hitlist'!$AA:$AA,MATCH(D14,'Company Hitlist'!$A:$A,0)),) | O14: =IFERROR(INDEX('Company Hitlist'!$N:$N,MATCH(D14,'Company Hitlist'!$A:$A,0)),) | Q14: todo
A15: Sarah Clarke | B15: Speaker | C15: Chief Supply Chain & Technology Officer | D15: AEO Inc | H15: 29 | I15: TRUE | J15: TRUE | K15: TRUE | L15: FALSE | M15: FALSE | N15: =IFERROR(INDEX('Company Hitlist'!$AA:$AA,MATCH(D15,'Company Hitlist'!$A:$A,0)),) | O15: =IFERROR(INDEX('Company Hitlist'!$N:$N,MATCH(D15,'Company Hitlist'!$A:$A,0)),) | Q15: todo
A16: Joyce Cruts | B16: Speaker | C16: VP Supply Chain & Operations | D16: Acer | H16: 29 | I16: TRUE | J16: TRUE | K16: TRUE | L16: FALSE | M16: FALSE | N16: =IFERROR(INDEX('Company Hitlist'!$AA:$AA,MATCH(D16,'Company Hitlist'!$A:$A,0)),) | O16: =IFERROR(INDEX('Company Hitlist'!$N:$N,MATCH(D16,'Company Hitlist'!$A:$A,0)),) | Q16: todo
A17: Rasheed Mohamad | B17: Speaker | C17: EVP, Global Operations & Business Technology | D17: Alcatel-Lucent Enterprise | F17: Yes | G17: $1.2B (2024 est.; projected $1.3B in 2025) | H17: 29 | I17: TRUE | J17: TRUE | K17: TRUE | L17: FALSE | M17: FALSE | N17: =IFERROR(INDEX('Company Hitlist'!$AA:$AA,MATCH(D17,'Company Hitlist'!$A:$A,0)),) | O17: =IFERROR(INDEX('Company Hitlist'!$N:$N,MATCH(D17,'Company Hitlist'!$A:$A,0)),) | Q17: todo
A18: Linda Babilo | B18: Speaker | C18: Vice President, Global Supply Chain | D18: Arlon Graphics | H18: 29 | I18: TRUE | J18: TRUE | K18: TRUE | L18: FALSE | M18: FALSE | N18: =IFERROR(INDEX('Company Hitlist'!$AA:$AA,MATCH(D18,'Company Hitlist'!$A:$A,0)),) | O18: =IFERROR(INDEX('Company Hitlist'!$N:$N,MATCH(D18,'Company Hitlist'!$A:$A,0)),) | Q18: todo
A19: Gary Horsfield | B19: Speaker | C19: Chief Supply Chain Officer | D19: BIC | H19: 29 | I19: TRUE | J19: TRUE | K19: TRUE | L19: FALSE | M19: FALSE | N19: =IFERROR(INDEX('Company Hitlist'!$AA:$AA,MATCH(D19,'Company Hitlist'!$A:$A,0)),) | O19: =IFERROR(INDEX('Company Hitlist'!$N:$N,MATCH(D19,'Company Hitlist'!$A:$A,0)),) | Q19: todo
A20: Rick Duley | B20: Speaker | C20: SVP Supply Chain | D20: Babylist | H20: 29 | I20: TRUE | J20: TRUE | K20: TRUE | L20: FALSE | M20: FALSE | N20: =IFERROR(INDEX('Company Hitlist'!$AA:$AA,MATCH(D20,'Company Hitlist'!$A:$A,0)),) | O20: =IFERROR(INDEX('Company Hitlist'!$N:$N,MATCH(D20,'Company Hitlist'!$A:$A,0)),) | Q20: todo
A21: Michael Frey | B21: Speaker | C21: Chief Supply Chain Officer | D21: Beiersdorf | H21: 29 | I21: TRUE | J21: TRUE | K21: TRUE | L21: FALSE | M21: FALSE | N21: =IFERROR(INDEX('Company Hitlist'!$AA:$AA,MATCH(D21,'Company Hitlist'!$A:$A,0)),) | O21: =IFERROR(INDEX('Company Hitlist'!$N:$N,MATCH(D21,'Company Hitlist'!$A:$A,0)),) | Q21: todo
A22: Gina Seit | B22: Speaker | C22: SVP, Operations | D22: Branch Furniture | F22: Yes | G22: $10M (2024 est.; projected $12M in 2025) | H22: 29 | I22: TRUE | J22: TRUE | K22: TRUE | L22: FALSE | M22: FALSE | N22: =IFERROR(INDEX('Company Hitlist'!$AA:$AA,MATCH(D22,'Company Hitlist'!$A:$A,0)),) | O22: =IFERROR(INDEX('Company Hitlist'!$N:$N,MATCH(D22,'Company Hitlist'!$A:$A,0)),) | Q22: todo
A23: Brad Blizzard | B23: Speaker | C23: Former VP, Logistics Operations & Product Delivery | D23: Bridgestone Americas | H23: 29 | I23: TRUE | J23: TRUE | K23: TRUE | L23: FALSE | M23: FALSE | N23: =IFERROR(INDEX('Company Hitlist'!$AA:$AA,MATCH(D23,'Company Hitlist'!$A:$A,0)),) | O23: =IFERROR(INDEX('Company Hitlist'!$N:$N,MATCH(D23,'Company Hitlist'!$A:$A,0)),) | Q23: todo
A24: Jeff Vertun | B24: Speaker | C24: SVP Global Supply Chain Collective | D24: CBRE | E24: United States | H24: 29 | I24: TRUE | J24: TRUE | K24: TRUE | L24: FALSE | M24: FALSE | N24: =IFERROR(INDEX('Company Hitlist'!$AA:$AA,MATCH(D24,'Company Hitlist'!$A:$A,0)),) | O24: =IFERROR(INDEX('Company Hitlist'!$N:$N,MATCH(D24,'Company Hitlist'!$A:$A,0)),) | Q24: todo
A25: Jesse Lydiatt | B25: Speaker | C25: VP Supply Chain | D25: California Innovations | E25: Canada | H25: 29 | I25: TRUE | J25: TRUE | K25: TRUE | L25: FALSE | M25: FALSE | N25: =IFERROR(INDEX('Company Hitlist'!$AA:$AA,MATCH(D25,'Company Hitlist'!$A:$A,0)),) | O25: =IFERROR(INDEX('Company Hitlist'!$N:$N,MATCH(D25,'Company Hitlist'!$A:$A,0)),) | Q25: todo
A26: Marc Kalmes | B26: Speaker | C26: SVP Global Supply Chain | D26: ChampionX | H26: 29 | I26: TRUE | J26: TRUE | K26: TRUE | L26: FALSE | M26: FALSE | N26: =IFERROR(INDEX('Company Hitlist'!$AA:$AA,MATCH(D26,'Company Hitlist'!$A:$A,0)),) | O26: =IFERROR(INDEX('Company Hitlist'!$N:$N,MATCH(D26,'Company Hitlist'!$A:$A,0)),) | Q26: todo
A27: Carlos Ruiz | B27: Speaker | C27: EVP, Chief Supply Chain Officer | D27: Church & Dwight | H27: 29 | I27: TRUE | J27: TRUE | K27: TRUE | L27: FALSE | M27: FALSE | N27: =IFERROR(INDEX('Company Hitlist'!$AA:$AA,MATCH(D27,'Company Hitlist'!$A:$A,0)),) | O27: =IFERROR(INDEX('Company Hitlist'!$N:$N,MATCH(D27,'Company Hitlist'!$A:$A,0)),) | Q27: todo
A28: Amalia Londono | B28: Speaker | C28: EVP End to End Supply Chain North America | D28: Colgate-Palmolive | E28: United States | H28: 29 | I28: TRUE | J28: TRUE | K28: TRUE | L28: FALSE | M28: FALSE | N28: =IFERROR(INDEX('Company Hitlist'!$AA:$AA,MATCH(D28,'Company Hitlist'!$A:$A,0)),) | O28: =IFERROR(INDEX('Company Hitlist'!$N:$N,MATCH(D28,'Company Hitlist'!$A:$A,0)),) | Q28: todo
A29: Rick Goe | B29: Speaker | C29: SVP, Supply Chain | D29: Distribution Management | H29: 29 | I29: TRUE | J29: TRUE | K29: TRUE | L29: FALSE | M29: FALSE | N29: =IFERROR(INDEX('Company Hitlist'!$AA:$AA,MATCH(D29,'Company Hitlist'!$A:$A,0)),) | O29: =IFERROR(INDEX('Company Hitlist'!$N:$N,MATCH(D29,'Company Hitlist'!$A:$A,0)),) | Q29: todo
A30: Rod West | B30: Speaker | C30: EVP, Global Supply Chain | D30: Dollar General | H30: 29 | I30: TRUE | J30: TRUE | K30: TRUE | L30: FALSE | M30: FALSE | N30: =IFERROR(INDEX('Company Hitlist'!$AA:$AA,MATCH(D30,'Company Hitlist'!$A:$A,0)),) | O30: =IFERROR(INDEX('Company Hitlist'!$N:$N,MATCH(D30,'Company Hitlist'!$A:$A,0)),) | Q30: todo
A31: Toni Buhrke | B31: Speaker | C31: VP of Engineering and Operations | D31: Dot Ai | F31: Yes | H31: 29 | I31: TRUE | J31: TRUE | K31: TRUE | L31: FALSE | M31: FALSE | N31: =IFERROR(INDEX('Company Hitlist'!$AA:$AA,MATCH(D31,'Company Hitlist'!$A:$A,0)),) | O31: =IFERROR(INDEX('Company Hitlist'!$N:$N,MATCH(D31,'Company Hitlist'!$A:$A,0)),) | Q31: todo
A32: Miguel Martins da Silva | B32: Speaker | C32: Group Chief Supply Chain Officer | D32: Dr. Max BDC | H32: 29 | I32: TRUE | J32: TRUE | K32: TRUE | L32: FALSE | M32: FALSE | N32: =IFERROR(INDEX('Company Hitlist'!$AA:$AA,MATCH(D32,'Company Hitlist'!$A:$A,0)),) | O32: =IFERROR(INDEX('Company Hitlist'!$N:$N,MATCH(D32,'Company Hitlist'!$A:$A,0)),) | Q32: todo
A33: Sachin Mariguddi | B33: Speaker | C33: Chief Supply Chain Officer, Americas | D33: Elida Beauty | H33: 29 | I33: TRUE | J33: TRUE | K33: TRUE | L33: FALSE | M33: FALSE | N33: =IFERROR(INDEX('Company Hitlist'!$AA:$AA,MATCH(D33,'Company Hitlist'!$A:$A,0)),) | O33: =IFERROR(INDEX('Company Hitlist'!$N:$N,MATCH(D33,'Company Hitlist'!$A:$A,0)),) | Q33: todo
A34: Julian VanErlach | B34: Speaker | C34: SVP, Global Supply Chain & Customer Service | D34: FabFitFun | H34: 29 | I34: TRUE | J34: TRUE | K34: TRUE | L34: FALSE | M34: FALSE | N34: =IFERROR(INDEX('Company Hitlist'!$AA:$AA,MATCH(D34,'Company Hitlist'!$A:$A,0)),) | O34: =IFERROR(INDEX('Company Hitlist'!$N:$N,MATCH(D34,'Company Hitlist'!$A:$A,0)),) | Q34: todo
A35: Michael Gambino | B35: Speaker | C35: VP Operations | D35: Fasteners Inc | F35: Yes | G35: $50M (2024 est.; projected $55M in 2025) | H35: 29 | I35: TRUE | J35: TRUE | K35: TRUE | L35: FALSE | M35: FALSE | N35: =IFERROR(INDEX('Company Hitlist'!$AA:$AA,MATCH(D35,'Company Hitlist'!$A:$A,0)),) | O35: =IFERROR(INDEX('Company Hitlist'!$N:$N,MATCH(D35,'Company Hitlist'!$A:$A,0)),) | Q35: todo
A36: Rebecca Linz | B36: Speaker | C36: VP of Supply Chain | D36: Force of Nature Meats | H36: 29 | I36: TRUE | J36: TRUE | K36: TRUE | L36: FALSE | M36: FALSE | N36: =IFERROR(INDEX('Company Hitlist'!$AA:$AA,MATCH(D36,'Company Hitlist'!$A:$A,0)),) | O36: =IFERROR(INDEX('Company Hitlist'!$N:$N,MATCH(D36,'Company Hitlist'!$A:$A,0)),) | Q36: todo
A37: Douglas Cantriel | B37: Speaker | C37: Head of North American Transportation & Modernization | D37: Ford Motor Company | H37: 29 | I37: TRUE | J37: TRUE | K37: TRUE | L37: FALSE | M37: FALSE | N37: =IFERROR(INDEX('Company Hitlist'!$AA:$AA,MATCH(D37,'Company Hitlist'!$A:$A,0)),) | O37: =IFERROR(INDEX('Company Hitlist'!$N:$N,MATCH(D37,'Company Hitlist'!$A:$A,0)),) | Q37: todo
A38: Jamie Saucedo | B38: Speaker | C38: Vice President, Business Operations | D38: GXO | F38: Yes | G38: $10.4B (2024; projected $11B in 2025) | H38: 29 | I38: TRUE | J38: TRUE | K38: TRUE | L38: FALSE | M38: FALSE | N38: =IFERROR(INDEX('Company Hitlist'!$AA:$AA,MATCH(D38,'Company Hitlist'!$A:$A,0)),) | O38: =IFERROR(INDEX('Company Hitlist'!$N:$N,MATCH(D38,'Company Hitlist'!$A:$A,0)),) | Q38: todo
A39: Mohamed El Shami | B39: Speaker | C39: Chief Supply Chain Officer | D39: Garlock Printing & Converting | H39: 29 | I39: TRUE | J39: TRUE | K39: TRUE | L39: FALSE | M39: FALSE | N39: =IFERROR(INDEX('Company Hitlist'!$AA:$AA,MATCH(D39,'Company Hitlist'!$A:$A,0)),) | O39: =IFERROR(INDEX('Company Hitlist'!$N:$N,MATCH(D39,'Company Hitlist'!$A:$A,0)),) | Q39: todo
A40: Christopher Longhito | B40: Speaker | C40: SVP & Chief Supply Chain Officer | D40: Global Industrial Company | H40: 29 | I40: TRUE | J40: TRUE | K40: TRUE | L40: FALSE | M40: FALSE | N40: =IFERROR(INDEX('Company Hitlist'!$AA:$AA,MATCH(D40,'Company Hitlist'!$A:$A,0)),) | O40: =IFERROR(INDEX('Company Hitlist'!$N:$N,MATCH(D40,'Company Hitlist'!$A:$A,0)),) | Q40: todo
...
